

# Generated at 2024-06-03 11:52:05.696931
```python
    loop = asyncio.new_event_loop()
    asyncio.set_event_loop(loop)

    # Test case 1: Chaining two asyncio Futures
    a = Future()
    b = Future()
    chain_future(a, b)

    a.set_result(42)
    assert b.result() == 42

    # Test case 2: Chaining with an exception
    a = Future()
    b = Future()
    chain_future(a, b)

    try:
        raise ValueError("Test exception")
    except ValueError as e:
        a.set_exception(e)

    try:
        b.result()
    except ValueError as e:
        assert str(e) == "Test exception"

    # Test case 3: Chaining a concurrent.futures.Future to an asyncio Future
    a = futures.Future()
    b = Future()
    chain_future(a, b)

    a.set_result(99)
    assert b.result() == 99

    # Test case 

# Generated at 2024-06-03 11:52:09.435875
```python
    loop = asyncio.new_event_loop()
    asyncio.set_event_loop(loop)

    a = Future()
    b = Future()

    chain_future(a, b)

    # Test result propagation
    a.set_result(42)
    assert b.result() == 42

    # Test exception propagation
    a = Future()
    b = Future()
    chain_future(a, b)
    try:
        raise ValueError("Test exception")
    except ValueError as e:
        a.set_exception(e)
    assert isinstance(b.exception(), ValueError)
    assert str(b.exception()) == "Test exception"

    # Test cancellation propagation
    a = Future()
    b = Future()
    chain_future(a, b)
    a.cancel()
    assert b.cancelled()

    loop.close()
```

# Generated at 2024-06-03 11:52:15.311004
```python
    loop = asyncio.new_event_loop()
    asyncio.set_event_loop(loop)

    # Test case 1: Chaining two asyncio Futures
    a = Future()
    b = Future()
    chain_future(a, b)

    a.set_result(42)
    assert b.result() == 42

    # Test case 2: Chaining with an exception
    a = Future()
    b = Future()
    chain_future(a, b)

    try:
        raise ValueError("Test error")
    except ValueError as e:
        a.set_exception(e)
    
    try:
        b.result()
    except ValueError as e:
        assert str(e) == "Test error"

    # Test case 3: Chaining with concurrent.futures.Future
    a = futures.Future()
    b = Future()
    chain_future(a, b)

    a.set_result(99)
    assert b.result() == 99

    # Test case 4: Ch

# Generated at 2024-06-03 11:52:17.578443
```python
    class TestClass:
        def __init__(self):
            self.executor = DummyExecutor()

        @run_on_executor
        def test_method(self, x):
            return x * 2

    async def main():
        obj = TestClass()
        future = obj.test_method(5)
        result = await future
        assert result == 10

    asyncio.run(main())
```

# Generated at 2024-06-03 11:52:19.804863
```python
    def sample_function(x, y):
        return x + y

    executor = DummyExecutor()
    future = executor.submit(sample_function, 2, 3)
    assert future.result() == 5

    def exception_function():
        raise ValueError("An error occurred")

    future = executor.submit(exception_function)
    try:
        future.result()
    except ValueError as e:
        assert str(e) == "An error occurred"
```

# Generated at 2024-06-03 11:52:24.070186
```python
    loop = asyncio.new_event_loop()
    asyncio.set_event_loop(loop)

    # Test case 1: Chaining two asyncio Futures
    a = Future()
    b = Future()
    chain_future(a, b)

    a.set_result(42)
    assert b.result() == 42

    # Test case 2: Chaining two concurrent.futures Futures
    a = futures.Future()
    b = futures.Future()
    chain_future(a, b)

    a.set_result(42)
    assert b.result() == 42

    # Test case 3: Chaining with exception
    a = Future()
    b = Future()
    chain_future(a, b)

    try:
        raise ValueError("Test error")
    except ValueError as e:
        a.set_exception(e)
    
    try:
        b.result()
    except ValueError as e:
        assert str(e) == "Test error"

    # Test case 4: Ch

# Generated at 2024-06-03 11:52:29.514862
```python
    loop = asyncio.new_event_loop()
    asyncio.set_event_loop(loop)

    a = Future()
    b = Future()

    chain_future(a, b)

    # Test result propagation
    a.set_result(42)
    assert b.result() == 42

    # Test exception propagation
    a = Future()
    b = Future()
    chain_future(a, b)
    try:
        raise ValueError("Test error")
    except ValueError as e:
        a.set_exception(e)
    assert isinstance(b.exception(), ValueError)
    assert str(b.exception()) == "Test error"

    # Test cancellation propagation
    a = Future()
    b = Future()
    chain_future(a, b)
    a.cancel()
    assert b.cancelled()

    loop.close()
```

# Generated at 2024-06-03 11:52:32.831331
```python
    class TestClass:
        def __init__(self):
            self.executor = DummyExecutor()

        @run_on_executor
        def add(self, x, y):
            return x + y

    async def main():
        obj = TestClass()
        future = obj.add(1, 2)
        result = await future
        assert result == 3

    asyncio.run(main())
```

# Generated at 2024-06-03 11:52:38.241079
```python
    loop = asyncio.new_event_loop()
    asyncio.set_event_loop(loop)

    # Test case 1: Chaining two asyncio Futures
    a = Future()
    b = Future()
    chain_future(a, b)

    a.set_result(42)
    assert b.result() == 42

    # Test case 2: Chaining with exception
    a = Future()
    b = Future()
    chain_future(a, b)

    try:
        raise ValueError("Test error")
    except ValueError as e:
        a.set_exception(e)
    
    try:
        b.result()
    except ValueError as e:
        assert str(e) == "Test error"

    # Test case 3: Chaining with concurrent.futures.Future
    a = futures.Future()
    b = Future()
    chain_future(a, b)

    a.set_result(99)
    assert b.result() == 99

    # Test case 4: Chaining

# Generated at 2024-06-03 11:52:42.751780
```python
    loop = asyncio.new_event_loop()
    asyncio.set_event_loop(loop)

    # Test case 1: Chaining two asyncio Futures
    a = Future()
    b = Future()
    chain_future(a, b)

    a.set_result(42)
    assert b.result() == 42

    # Test case 2: Chaining with an exception
    a = Future()
    b = Future()
    chain_future(a, b)

    try:
        raise ValueError("Test error")
    except ValueError as e:
        a.set_exception(e)
    
    try:
        b.result()
    except ValueError as e:
        assert str(e) == "Test error"

    # Test case 3: Chaining a concurrent.futures.Future to an asyncio Future
    a = futures.Future()
    b = Future()
    chain_future(a, b)

    a.set_result(99)
    assert b.result() == 99

    # Test case