

# Generated at 2024-03-18 08:15:13.006998
```python
    # Assume the following imports have been made for the test context
    import unittest
    from unittest.mock import Mock

    class TestFutureSetResultUnlessCancelled(unittest.TestCase):
        def test_set_result_on_non_cancelled_future(self):
            future = Future()
            future_set_result_unless_cancelled(future, "result")
            self.assertEqual(future.result(), "result")

        def test_set_result_on_cancelled_future(self):
            future = Future()
            future.cancel()
            future_set_result_unless_cancelled(future, "result")
            self.assertTrue(future.cancelled())

        def test_set_result_on_already_completed_future(self):
            future = Future()
            future.set_result("initial")
            future_set_result_unless_cancelled(future, "new_result")
            self.assertEqual(future.result(), "initial")

    if __name__ == "__main__":
        unittest.main()
```

# Generated at 2024-03-18 08:15:20.819654
```python
    from tornado.concurrent import Future, chain_future
    import unittest

    class TestChainFuture(unittest.TestCase):
        def test_chain_success(self):
            a = Future()
            b = Future()
            chain_future(a, b)
            result = object()
            a.set_result(result)
            self.assertTrue(b.done())
            self.assertEqual(b.result(), result)

        def test_chain_exception(self):
            a = Future()
            b = Future()
            chain_future(a, b)
            try:
                raise Exception("Test exception")
            except Exception as e:
                a.set_exception(e)
            self.assertTrue(b.done())
            self.assertIsInstance(b.exception(), Exception)
            self.assertEqual(str(b.exception()), "Test exception")

        def test_chain_cancelled(self):
            a = Future()
            b = Future()
            chain_future(a, b)
            b.cancel()
            a.set_result(object())
            self.assertTrue(b.cancelled())

    if __name__ == '__main__':
        unittest.main()


# Generated at 2024-03-18 08:15:27.261655
```python
    from tornado.concurrent import Future, chain_future
    import unittest

    class TestChainFuture(unittest.TestCase):
        def test_chain_success(self):
            a = Future()
            b = Future()
            chain_future(a, b)
            result = object()
            a.set_result(result)
            self.assertTrue(b.done())
            self.assertEqual(b.result(), result)

        def test_chain_exception(self):
            a = Future()
            b = Future()
            chain_future(a, b)
            try:
                raise Exception("Test exception")
            except Exception as e:
                a.set_exception(e)
            self.assertTrue(b.done())
            self.assertIsInstance(b.exception(), Exception)
            self.assertEqual(str(b.exception()), "Test exception")

        def test_chain_cancelled(self):
            a = Future()
            b = Future()
            chain_future(a, b)
            b.cancel()
            a.set_result(object())
            self.assertTrue(b.cancelled())

    if __name__ == '__main__':
        unittest.main()


# Generated at 2024-03-18 08:15:36.780904
```python
    from tornado.testing import AsyncTestCase, gen_test

    class TestChainFuture(AsyncTestCase):
        @gen_test
        async def test_chain(self):
            future1 = Future()
            future2 = Future()

            chain_future(future1, future2)

            # Set a result on future1 and ensure it propagates to future2
            result = "test result"
            future1.set_result(result)
            self.assertEqual(await future2, result)

            # Reset futures for exception test
            future1 = Future()
            future2 = Future()
            chain_future(future1, future2)

            # Set an exception on future1 and ensure it propagates to future2
            try:
                raise ValueError("test exception")
            except ValueError as e:
                future1.set_exception(e)

            with self.assertRaises(ValueError):
                await future2

            # Test that cancelling future2 does not affect future1
            future1 = Future()
            future2

# Generated at 2024-03-18 08:15:42.672238
```python
    from tornado.concurrent import Future, chain_future
    import unittest

    class TestChainFuture(unittest.TestCase):
        def test_chain_success(self):
            a = Future()
            b = Future()
            chain_future(a, b)
            result = object()
            a.set_result(result)
            self.assertTrue(b.done())
            self.assertEqual(b.result(), result)

        def test_chain_exception(self):
            a = Future()
            b = Future()
            chain_future(a, b)
            try:
                raise Exception("Test exception")
            except Exception as e:
                a.set_exception(e)
            self.assertTrue(b.done())
            self.assertIsInstance(b.exception(), Exception)
            self.assertEqual(str(b.exception()), "Test exception")

        def test_chain_cancelled(self):
            a = Future()
            b = Future()
            chain_future(a, b)
            b.cancel()
            a.set_result(object())
            self.assertTrue(b.cancelled())

        def test_chain_already_done(self):
            a = Future()


# Generated at 2024-03-18 08:15:43.443012
```python
import unittest
from unittest.mock import Mock


# Generated at 2024-03-18 08:15:51.199650
```python
    from tornado.concurrent import Future, chain_future
    import unittest

    class TestChainFuture(unittest.TestCase):
        def test_chain_success(self):
            a = Future()
            b = Future()
            chain_future(a, b)
            result = object()
            a.set_result(result)
            self.assertTrue(b.done())
            self.assertEqual(b.result(), result)

        def test_chain_exception(self):
            a = Future()
            b = Future()
            chain_future(a, b)
            try:
                raise Exception("Test exception")
            except Exception as e:
                a.set_exception(e)
            self.assertTrue(b.done())
            self.assertIsInstance(b.exception(), Exception)
            self.assertEqual(str(b.exception()), "Test exception")

        def test_chain_cancelled(self):
            a = Future()
            b = Future()
            chain_future(a, b)
            b.cancel()
            a.set_result(object())
            self.assertTrue(b.cancelled())

        def test_chain_already_done(self):
            a = Future()


# Generated at 2024-03-18 08:15:53.110544
```python
import unittest


# Generated at 2024-03-18 08:16:15.970495
```python
    from tornado.testing import AsyncTestCase, gen_test

    class TestChainFuture(AsyncTestCase):
        @gen_test
        async def test_chain(self):
            future1 = Future()
            future2 = Future()

            chain_future(future1, future2)

            # Set a result on future1 and ensure it propagates to future2
            result = "test result"
            future1.set_result(result)
            self.assertEqual(await future2, result)

            # Reset futures for exception test
            future1 = Future()
            future2 = Future()
            chain_future(future1, future2)

            # Set an exception on future1 and ensure it propagates to future2
            try:
                raise ValueError("test exception")
            except ValueError as e:
                future1.set_exception(e)

            with self.assertRaises(ValueError):
                await future2

            # Test that cancelling future2 does not affect future1
            future1 = Future()
            future2

# Generated at 2024-03-18 08:16:22.475729
```python
    # Assume the following imports have been made for the test context
    import unittest
    from unittest.mock import Mock

    class TestFutureSetResultUnlessCancelled(unittest.TestCase):
        def test_set_result_on_non_cancelled_future(self):
            future = Future()
            future_set_result_unless_cancelled(future, "result")
            self.assertEqual(future.result(), "result")

        def test_set_result_on_cancelled_future(self):
            future = Future()
            future.cancel()
            future_set_result_unless_cancelled(future, "result")
            self.assertTrue(future.cancelled())

        def test_set_result_on_already_completed_future(self):
            future = Future()
            future.set_result("initial")
            future_set_result_unless_cancelled(future, "new_result")
            self.assertEqual(future.result(), "initial")

    if __name__ == "__main__":
        unittest.main()
```

# Generated at 2024-03-18 08:16:31.355204
```python
import unittest


# Generated at 2024-03-18 08:16:39.948911
```python
    from tornado.concurrent import Future, chain_future
    import unittest

    class TestChainFuture(unittest.TestCase):
        def test_chain_success(self):
            a = Future()
            b = Future()
            chain_future(a, b)
            result = object()
            a.set_result(result)
            self.assertTrue(b.done())
            self.assertEqual(b.result(), result)

        def test_chain_exception(self):
            a = Future()
            b = Future()
            chain_future(a, b)
            try:
                raise Exception("Test exception")
            except Exception as e:
                a.set_exception(e)
            self.assertTrue(b.done())
            self.assertIsInstance(b.exception(), Exception)
            self.assertEqual(str(b.exception()), "Test exception")

        def test_chain_cancelled(self):
            a = Future()
            b = Future()
            chain_future(a, b)
            b.cancel()
            a.set_result(object())
            self.assertTrue(b.cancelled())

    unittest.main()
```

# Generated at 2024-03-18 08:16:40.693386
```python
import unittest


# Generated at 2024-03-18 08:16:42.650303
```python
import unittest


# Generated at 2024-03-18 08:16:51.034401
```python
    from tornado.concurrent import Future, chain_future
    import unittest

    class TestChainFuture(unittest.TestCase):
        def test_chain_success(self):
            a = Future()
            b = Future()
            chain_future(a, b)
            result = object()
            a.set_result(result)
            self.assertTrue(b.done())
            self.assertEqual(b.result(), result)

        def test_chain_exception(self):
            a = Future()
            b = Future()
            chain_future(a, b)
            try:
                raise Exception("Test exception")
            except Exception as e:
                a.set_exception(e)
            self.assertTrue(b.done())
            self.assertIsInstance(b.exception(), Exception)
            self.assertEqual(str(b.exception()), "Test exception")

        def test_chain_cancelled(self):
            a = Future()
            b = Future()
            chain_future(a, b)
            b.cancel()
            a.set_result(object())
            self.assertTrue(b.cancelled())

    if __name__ == '__main__':
        unittest.main()


# Generated at 2024-03-18 08:16:58.133230
```python
import unittest


# Generated at 2024-03-18 08:17:04.562716
```python
    from tornado.testing import AsyncTestCase, gen_test

    class TestChainFuture(AsyncTestCase):
        @gen_test
        async def test_chain(self):
            future1 = Future()
            future2 = Future()

            chain_future(future1, future2)

            # Set a result on future1 and check if future2 gets the same result
            result = "test result"
            future1.set_result(result)
            self.assertEqual(await future2, result)

            # Reset futures for exception test
            future1 = Future()
            future2 = Future()
            chain_future(future1, future2)

            # Set an exception on future1 and check if future2 gets the same exception
            try:
                raise ValueError("test exception")
            except ValueError as e:
                future1.set_exception(e)

            with self.assertRaises(ValueError) as context:
                await future2
            self.assertEqual(str(context.exception), "test exception")

            # Test that if future

# Generated at 2024-03-18 08:17:05.254068
```python
import unittest


# Generated at 2024-03-18 08:17:12.094583
```python
    from tornado.concurrent import Future, chain_future
    import unittest

    class TestChainFuture(unittest.TestCase):
        def test_chain_success(self):
            a = Future()
            b = Future()
            chain_future(a, b)
            result = object()
            a.set_result(result)
            self.assertTrue(b.done())
            self.assertEqual(b.result(), result)

        def test_chain_exception(self):
            a = Future()
            b = Future()
            chain_future(a, b)
            try:
                raise Exception("Test exception")
            except Exception as e:
                a.set_exception(e)
            self.assertTrue(b.done())
            self.assertIsInstance(b.exception(), Exception)
            self.assertEqual(str(b.exception()), "Test exception")

        def test_chain_cancelled(self):
            a = Future()
            b = Future()
            chain_future(a, b)
            b.cancel()
            a.set_result(object())
            self.assertTrue(b.cancelled())

        def test_chain_already_done(self):
            a = Future()


# Generated at 2024-03-18 08:17:18.966373
```python
    # Assume the following imports have been made for the test context
    import unittest
    from unittest.mock import Mock

    class TestFutureSetExceptionUnlessCancelled(unittest.TestCase):
        def test_set_exception_on_non_cancelled_future(self):
            future = Future()
            exception = Exception("Test exception")
            future_set_exception_unless_cancelled(future, exception)
            self.assertTrue(future.done())
            self.assertEqual(future.exception(), exception)

        def test_set_exception_on_cancelled_future(self):
            future = Future()
            future.cancel()
            exception = Exception("Test exception")
            future_set_exception_unless_cancelled(future, exception)
            self.assertTrue(future.cancelled())
            self.assertIsNone(future.exception())

        def test_logging_on_cancelled_future(self):
            future = Future()
            future.cancel()
            exception = Exception("Test exception")
            with self.assertLogs('tornado.application', level='ERROR') as cm:
                future_set_exception_unless

# Generated at 2024-03-18 08:17:42.848824
```python
    # Create a Future object
    future = Future()

    # Set an exception on the future unless it is cancelled
    exc = Exception("Test exception")
    future_set_exception_unless_cancelled(future, exc)

    # Check if the future has the exception set
    assert future.exception() == exc

    # Cancel the future
    future.cancel()

    # Try setting another exception, which should not be set due to cancellation
    another_exc = Exception("Another test exception")
    future_set_exception_unless_cancelled(future, another_exc)

    # The future should still have the original exception
    assert future.exception() == exc

    # There should be no logging of the second exception since it was not set
```

# Generated at 2024-03-18 08:17:49.444916
```python
    from tornado.testing import AsyncTestCase, gen_test

    class TestChainFuture(AsyncTestCase):
        @gen_test
        async def test_chain(self):
            future1 = Future()
            future2 = Future()

            chain_future(future1, future2)

            # Set a result on future1 and check if future2 gets the same result
            result = "test result"
            future1.set_result(result)
            self.assertEqual(await future2, result)

            # Reset futures for exception test
            future1 = Future()
            future2 = Future()
            chain_future(future1, future2)

            # Set an exception on future1 and check if future2 gets the same exception
            try:
                raise ValueError("test exception")
            except ValueError as e:
                future1.set_exception(e)

            with self.assertRaises(ValueError) as context:
                await future2
            self.assertEqual(str(context.exception), "test exception")

            # Test that if future

# Generated at 2024-03-18 08:17:50.890197
```python
import unittest


# Generated at 2024-03-18 08:17:56.900628
```python
    from tornado.concurrent import Future, chain_future
    import unittest

    class TestChainFuture(unittest.TestCase):
        def test_chain_success(self):
            a = Future()
            b = Future()
            chain_future(a, b)
            result = object()
            a.set_result(result)
            self.assertTrue(b.done())
            self.assertEqual(b.result(), result)

        def test_chain_exception(self):
            a = Future()
            b = Future()
            chain_future(a, b)
            try:
                raise Exception("Test exception")
            except Exception as e:
                a.set_exception(e)
            self.assertTrue(b.done())
            self.assertIsInstance(b.exception(), Exception)
            self.assertEqual(str(b.exception()), "Test exception")

        def test_chain_cancelled(self):
            a = Future()
            b = Future()
            chain_future(a, b)
            b.cancel()
            a.set_result(object())
            self.assertTrue(b.cancelled())

        def test_chain_already_done(self):
            a = Future()


# Generated at 2024-03-18 08:18:00.303067
```python
    try:
        future = Future()
        future.cancel()
        exc = Exception("Test exception")
        future_set_exception_unless_cancelled(future, exc)
        assert future.cancelled()
        assert not future.done()

        future = Future()
        exc = Exception("Test exception")
        future_set_exception_unless_cancelled(future, exc)
        assert future.exception() == exc
        assert future.done()
    except Exception as e:
        assert False, f"Unexpected exception raised: {e}"
```

# Generated at 2024-03-18 08:18:07.303709
```python
    from tornado.concurrent import Future, chain_future
    import unittest

    class TestChainFuture(unittest.TestCase):
        def test_chain_success(self):
            a = Future()
            b = Future()
            chain_future(a, b)
            result = object()
            a.set_result(result)
            self.assertTrue(b.done())
            self.assertEqual(b.result(), result)

        def test_chain_exception(self):
            a = Future()
            b = Future()
            chain_future(a, b)
            try:
                raise Exception("Test exception")
            except Exception as e:
                a.set_exception(e)
            self.assertTrue(b.done())
            self.assertIsInstance(b.exception(), Exception)
            self.assertEqual(str(b.exception()), "Test exception")

        def test_chain_cancelled(self):
            a = Future()
            b = Future()
            chain_future(a, b)
            b.cancel()
            a.set_result(object())
            self.assertTrue(b.cancelled())

        def test_chain_already_done(self):
            a = Future()


# Generated at 2024-03-18 08:18:14.228916
```python
    from tornado.concurrent import Future, chain_future
    import unittest

    class TestChainFuture(unittest.TestCase):
        def test_chain_success(self):
            a = Future()
            b = Future()
            chain_future(a, b)
            result = object()
            a.set_result(result)
            self.assertTrue(b.done())
            self.assertEqual(b.result(), result)

        def test_chain_exception(self):
            a = Future()
            b = Future()
            chain_future(a, b)
            try:
                raise Exception("Test exception")
            except Exception as e:
                a.set_exception(e)
            self.assertTrue(b.done())
            self.assertIsInstance(b.exception(), Exception)
            self.assertEqual(str(b.exception()), "Test exception")

        def test_chain_cancelled(self):
            a = Future()
            b = Future()
            chain_future(a, b)
            b.cancel()
            a.set_result(object())
            self.assertTrue(b.cancelled())

    if __name__ == '__main__':
        unittest.main()


# Generated at 2024-03-18 08:18:20.500770
```python
    from tornado.concurrent import Future, chain_future
    import unittest

    class TestChainFuture(unittest.TestCase):
        def test_chain_success(self):
            a = Future()
            b = Future()
            chain_future(a, b)
            result = object()
            a.set_result(result)
            self.assertTrue(b.done())
            self.assertEqual(b.result(), result)

        def test_chain_exception(self):
            a = Future()
            b = Future()
            chain_future(a, b)
            try:
                raise Exception("Test exception")
            except Exception as e:
                a.set_exception(e)
            self.assertTrue(b.done())
            self.assertIsInstance(b.exception(), Exception)
            self.assertEqual(str(b.exception()), "Test exception")

        def test_chain_cancelled(self):
            a = Future()
            b = Future()
            chain_future(a, b)
            b.cancel()
            a.set_result(object())
            self.assertTrue(b.cancelled())

        def test_chain_already_done(self):
            a = Future()


# Generated at 2024-03-18 08:18:21.605601
```python
import unittest


# Generated at 2024-03-18 08:18:30.363355
```python
    from tornado.testing import AsyncTestCase, gen_test

    class TestChainFuture(AsyncTestCase):
        @gen_test
        async def test_chain(self):
            future1 = Future()
            future2 = Future()

            chain_future(future1, future2)

            # Set a result on future1 and ensure it propagates to future2
            result = "test result"
            future1.set_result(result)
            self.assertEqual(await future2, result)

            # Reset futures for exception test
            future1 = Future()
            future2 = Future()
            chain_future(future1, future2)

            # Set an exception on future1 and ensure it propagates to future2
            try:
                raise ValueError("test exception")
            except ValueError as e:
                future1.set_exception(e)

            with self.assertRaises(ValueError):
                await future2

            # Test that cancelling future2 does not affect future1
            future1 = Future()
            future2

# Generated at 2024-03-18 08:18:50.381877
```python
    from tornado.concurrent import Future, chain_future
    import unittest

    class TestChainFuture(unittest.TestCase):
        def test_chain_success(self):
            a = Future()
            b = Future()
            chain_future(a, b)
            result = object()
            a.set_result(result)
            self.assertTrue(b.done())
            self.assertEqual(b.result(), result)

        def test_chain_exception(self):
            a = Future()
            b = Future()
            chain_future(a, b)
            try:
                raise Exception("Test exception")
            except Exception as e:
                a.set_exception(e)
            self.assertTrue(b.done())
            self.assertIsInstance(b.exception(), Exception)
            self.assertEqual(str(b.exception()), "Test exception")

        def test_chain_cancelled(self):
            a = Future()
            b = Future()
            chain_future(a, b)
            b.cancel()
            a.set_result(object())
            self.assertTrue(b.cancelled())

    unittest.main()
```

# Generated at 2024-03-18 08:18:57.915000
```python
    from tornado.concurrent import Future, chain_future
    import unittest

    class TestChainFuture(unittest.TestCase):
        def test_chain_success(self):
            a = Future()
            b = Future()
            chain_future(a, b)
            result = object()
            a.set_result(result)
            self.assertTrue(b.done())
            self.assertEqual(b.result(), result)

        def test_chain_exception(self):
            a = Future()
            b = Future()
            chain_future(a, b)
            try:
                raise Exception("Test exception")
            except Exception as e:
                a.set_exception(e)
            self.assertTrue(b.done())
            self.assertIsInstance(b.exception(), Exception)
            self.assertEqual(str(b.exception()), "Test exception")

        def test_chain_cancelled(self):
            a = Future()
            b = Future()
            chain_future(a, b)
            b.cancel()
            a.set_result(object())
            self.assertTrue(b.cancelled())

        def test_chain_already_done(self):
            a = Future()


# Generated at 2024-03-18 08:18:58.682358
```python
import unittest
from unittest.mock import Mock


# Generated at 2024-03-18 08:19:05.567583
```python
    from tornado.testing import AsyncTestCase, gen_test

    class TestChainFuture(AsyncTestCase):
        @gen_test
        async def test_chain(self):
            future1 = Future()
            future2 = Future()

            chain_future(future1, future2)

            # Set a result on future1 and check if future2 gets the same result
            result = "test result"
            future1.set_result(result)
            self.assertEqual(await future2, result)

            # Reset futures for exception test
            future1 = Future()
            future2 = Future()
            chain_future(future1, future2)

            # Set an exception on future1 and check if future2 gets the same exception
            try:
                raise ValueError("test exception")
            except ValueError as e:
                future1.set_exception(e)
                with self.assertRaises(ValueError) as context:
                    await future2
                self.assertEqual(str(context.exception), "test exception")

            # Test that if future

# Generated at 2024-03-18 08:19:15.237564
```python
    # Create a normal future and set a result
    normal_future = Future()
    future_set_result_unless_cancelled(normal_future, "normal result")
    assert normal_future.result() == "normal result"

    # Create a cancelled future and try to set a result
    cancelled_future = Future()
    cancelled_future.cancel()
    future_set_result_unless_cancelled(cancelled_future, "cancelled result")
    assert cancelled_future.cancelled()

    # Create a future, set an exception, then try to set a result
    exception_future = Future()
    exception_future.set_exception(RuntimeError("error"))
    try:
        future_set_result_unless_cancelled(exception_future, "exception result")
    except RuntimeError:
        pass  # Expected, as the future already has an exception set
    assert exception_future.exception() is not None
    assert isinstance(exception_future.exception(), RuntimeError)
```

# Generated at 2024-03-18 08:19:20.991360
```python
    try:
        # Create a Future object
        future = Future()

        # Cancel the future
        future.cancel()

        # Set an exception on the cancelled future
        exc = Exception("Test exception")
        future_set_exception_unless_cancelled(future, exc)

        # Since the future was cancelled, the exception should not be set,
        # and instead, it should be logged. The future should remain cancelled.
        assert future.cancelled()

        # Create another Future object
        future2 = Future()

        # Set an exception on the non-cancelled future
        future_set_exception_unless_cancelled(future2, exc)

        # The future should now have the exception set
        assert future2.exception() == exc

    except AssertionError:
        print("Test failed.")
    else:
        print("Test passed.")
```

# Generated at 2024-03-18 08:19:27.995433
```python
    # Assume the following imports have been made for the test context
    import unittest
    from unittest.mock import Mock

    class TestFutureSetExceptionUnlessCancelled(unittest.TestCase):
        def test_set_exception_on_non_cancelled_future(self):
            future = Future()
            exception = Exception("Test exception")
            future_set_exception_unless_cancelled(future, exception)
            self.assertTrue(future.done())
            self.assertEqual(future.exception(), exception)

        def test_no_exception_on_cancelled_future(self):
            future = Future()
            future.cancel()
            exception = Exception("Test exception")
            future_set_exception_unless_cancelled(future, exception)
            self.assertTrue(future.cancelled())

        def test_logging_on_cancelled_future(self):
            future = Future()
            future.cancel()
            exception = Exception("Test exception")
            with self.assertLogs('tornado.application', level='ERROR') as cm:
                future_set_exception_unless_cancelled(future, exception)
           

# Generated at 2024-03-18 08:19:36.578625
```python
    import unittest

    class TestDummyExecutor(unittest.TestCase):
        def test_submit_success(self):
            def dummy_function(x, y):
                return x + y

            executor = DummyExecutor()
            future = executor.submit(dummy_function, 1, 2)
            result = future.result()
            self.assertEqual(result, 3)

        def test_submit_exception(self):
            def dummy_function(x, y):
                raise ValueError("dummy error")

            executor = DummyExecutor()
            future = executor.submit(dummy_function, 1, 2)
            with self.assertRaises(ValueError) as context:
                future.result()
            self.assertEqual(str(context.exception), "dummy error")

    if __name__ == '__main__':
        unittest.main()
```

# Generated at 2024-03-18 08:19:46.679359
```python
    from tornado.concurrent import Future, chain_future
    import unittest

    class TestChainFuture(unittest.TestCase):
        def test_chain_success(self):
            a = Future()
            b = Future()
            chain_future(a, b)
            result = object()
            a.set_result(result)
            self.assertTrue(b.done())
            self.assertEqual(b.result(), result)

        def test_chain_exception(self):
            a = Future()
            b = Future()
            chain_future(a, b)
            try:
                raise Exception("Test exception")
            except Exception as e:
                a.set_exception(e)
            self.assertTrue(b.done())
            self.assertIsInstance(b.exception(), Exception)
            self.assertEqual(str(b.exception()), "Test exception")

        def test_chain_cancelled(self):
            a = Future()
            b = Future()
            chain_future(a, b)
            b.cancel()
            a.set_result(object())
            self.assertTrue(b.cancelled())

    if __name__ == '__main__':
        unittest.main()


# Generated at 2024-03-18 08:19:47.575730
```python
import unittest


# Generated at 2024-03-18 08:20:10.105148
```python
    from tornado.concurrent import Future, chain_future
    import unittest

    class TestChainFuture(unittest.TestCase):
        def test_chain_success(self):
            a = Future()
            b = Future()
            chain_future(a, b)
            result = object()
            a.set_result(result)
            self.assertTrue(b.done())
            self.assertEqual(b.result(), result)

        def test_chain_exception(self):
            a = Future()
            b = Future()
            chain_future(a, b)
            try:
                raise Exception("Test exception")
            except Exception as e:
                a.set_exception(e)
            self.assertTrue(b.done())
            self.assertIsInstance(b.exception(), Exception)
            self.assertEqual(str(b.exception()), "Test exception")

        def test_chain_cancelled(self):
            a = Future()
            b = Future()
            chain_future(a, b)
            b.cancel()
            a.set_result(object())
            self.assertTrue(b.cancelled())

    if __name__ == '__main__':
        unittest.main()


# Generated at 2024-03-18 08:20:16.482526
```python
    from tornado.concurrent import Future, chain_future
    import unittest

    class TestChainFuture(unittest.TestCase):
        def test_chain_success(self):
            a = Future()
            b = Future()
            chain_future(a, b)
            result = object()
            a.set_result(result)
            self.assertTrue(b.done())
            self.assertEqual(b.result(), result)

        def test_chain_exception(self):
            a = Future()
            b = Future()
            chain_future(a, b)
            try:
                raise Exception("Test exception")
            except Exception as e:
                a.set_exception(e)
            self.assertTrue(b.done())
            self.assertIsInstance(b.exception(), Exception)
            self.assertEqual(str(b.exception()), "Test exception")

        def test_chain_cancelled(self):
            a = Future()
            b = Future()
            chain_future(a, b)
            b.cancel()
            a.set_result(object())
            self.assertTrue(b.cancelled())

    if __name__ == '__main__':
        unittest.main()


# Generated at 2024-03-18 08:20:22.945028
```python
    from concurrent.futures import CancelledError

    def test_function(x, y):
        return x + y

    def test_function_raises_exception():
        raise ValueError("An error occurred")

    # Test normal function execution
    executor = DummyExecutor()
    future = executor.submit(test_function, 1, 2)
    assert future.result() == 3, "The result of 1 + 2 should be 3"

    # Test function that raises an exception
    future_exception = executor.submit(test_function_raises_exception)
    try:
        future_exception.result()
        assert False, "The function should have raised an exception"
    except ValueError as e:
        assert str(e) == "An error occurred", "The exception message should match"

    # Test cancelling the future before running
    future_cancel = executor.submit(test_function, 1, 2)
    cancelled = future_cancel.cancel()
    assert cancelled, "The future should be cancelled"
   

# Generated at 2024-03-18 08:20:28.810598
```python
    from tornado.concurrent import Future, chain_future
    import unittest

    class TestChainFuture(unittest.TestCase):
        def test_chain_success(self):
            a = Future()
            b = Future()
            chain_future(a, b)
            result = object()
            a.set_result(result)
            self.assertTrue(b.done())
            self.assertEqual(b.result(), result)

        def test_chain_exception(self):
            a = Future()
            b = Future()
            chain_future(a, b)
            try:
                raise Exception("Test exception")
            except Exception as e:
                a.set_exception(e)
            self.assertTrue(b.done())
            self.assertIsInstance(b.exception(), Exception)
            self.assertEqual(str(b.exception()), "Test exception")

        def test_chain_cancelled(self):
            a = Future()
            b = Future()
            chain_future(a, b)
            b.cancel()
            a.set_result(object())
            self.assertTrue(b.cancelled())

        def test_chain_already_done(self):
            a = Future()


# Generated at 2024-03-18 08:20:34.821115
```python
    from tornado.testing import AsyncTestCase, gen_test

    class TestChainFuture(AsyncTestCase):
        @gen_test
        async def test_chain(self):
            future1 = Future()
            future2 = Future()

            chain_future(future1, future2)

            # Set a result on future1 and ensure it propagates to future2
            result = "test result"
            future1.set_result(result)
            self.assertEqual(await future2, result)

            # Reset futures for exception test
            future1 = Future()
            future2 = Future()
            chain_future(future1, future2)

            # Set an exception on future1 and ensure it propagates to future2
            try:
                raise Exception("test exception")
            except Exception as e:
                future1.set_exception(e)

            with self.assertRaises(Exception) as context:
                await future2
            self.assertEqual(str(context.exception), "test exception")

            # Test that cancelling future2 does

# Generated at 2024-03-18 08:20:36.048471
```python
import unittest


# Generated at 2024-03-18 08:20:43.692452
```python
    from tornado.concurrent import Future, chain_future
    import unittest

    class TestChainFuture(unittest.TestCase):
        def test_chain_success(self):
            a = Future()
            b = Future()
            chain_future(a, b)
            result = object()
            a.set_result(result)
            self.assertTrue(b.done())
            self.assertEqual(b.result(), result)

        def test_chain_exception(self):
            a = Future()
            b = Future()
            chain_future(a, b)
            try:
                raise Exception("Test exception")
            except Exception as e:
                a.set_exception(e)
            self.assertTrue(b.done())
            self.assertIsInstance(b.exception(), Exception)
            self.assertEqual(str(b.exception()), "Test exception")

        def test_chain_cancelled(self):
            a = Future()
            b = Future()
            chain_future(a, b)
            b.cancel()
            a.set_result(object())
            self.assertTrue(b.cancelled())

        def test_chain_already_done(self):
            a = Future()


# Generated at 2024-03-18 08:20:53.573251
```python
    from tornado.concurrent import Future, chain_future
    import unittest

    class TestChainFuture(unittest.TestCase):
        def test_chain_success(self):
            a = Future()
            b = Future()
            chain_future(a, b)
            result = object()
            a.set_result(result)
            self.assertTrue(b.done())
            self.assertEqual(b.result(), result)

        def test_chain_exception(self):
            a = Future()
            b = Future()
            chain_future(a, b)
            try:
                raise Exception("Test exception")
            except Exception as e:
                a.set_exception(e)
            self.assertTrue(b.done())
            self.assertIsInstance(b.exception(), Exception)
            self.assertEqual(str(b.exception()), "Test exception")

        def test_chain_cancelled(self):
            a = Future()
            b = Future()
            chain_future(a, b)
            b.cancel()
            a.set_result(object())
            self.assertTrue(b.cancelled())

    if __name__ == '__main__':
        unittest.main()


# Generated at 2024-03-18 08:20:59.761367
```python
    from tornado.concurrent import Future, chain_future
    import unittest

    class TestChainFuture(unittest.TestCase):
        def test_chain_success(self):
            a = Future()
            b = Future()
            chain_future(a, b)
            result = object()
            a.set_result(result)
            self.assertTrue(b.done())
            self.assertEqual(b.result(), result)

        def test_chain_exception(self):
            a = Future()
            b = Future()
            chain_future(a, b)
            try:
                raise Exception("Test exception")
            except Exception as e:
                a.set_exception(e)
            self.assertTrue(b.done())
            self.assertIsInstance(b.exception(), Exception)
            self.assertEqual(str(b.exception()), "Test exception")

        def test_chain_cancelled(self):
            a = Future()
            b = Future()
            chain_future(a, b)
            b.cancel()
            a.set_result(object())
            self.assertTrue(b.cancelled())

    if __name__ == '__main__':
        unittest.main()


# Generated at 2024-03-18 08:21:08.284134
```python
    from tornado.concurrent import Future, chain_future
    import unittest

    class TestChainFuture(unittest.TestCase):
        def test_chain_success(self):
            a = Future()
            b = Future()
            chain_future(a, b)
            result = object()
            a.set_result(result)
            self.assertTrue(b.done())
            self.assertEqual(b.result(), result)

        def test_chain_exception(self):
            a = Future()
            b = Future()
            chain_future(a, b)
            try:
                raise Exception("Test exception")
            except Exception as e:
                a.set_exception(e)
            self.assertTrue(b.done())
            self.assertIsInstance(b.exception(), Exception)
            self.assertEqual(str(b.exception()), "Test exception")

        def test_chain_cancelled(self):
            a = Future()
            b = Future()
            chain_future(a, b)
            b.cancel()
            a.set_result(object())
            self.assertTrue(b.cancelled())

        def test_chain_already_done(self):
            a = Future()


# Generated at 2024-03-18 08:21:49.643670
```python
    from tornado.testing import AsyncTestCase, gen_test

    class TestChainFuture(AsyncTestCase):
        @gen_test
        async def test_chain(self):
            future1 = Future()
            future2 = Future()

            chain_future(future1, future2)

            # Set a result on future1 and check if future2 gets the same result
            result = "test result"
            future1.set_result(result)
            self.assertEqual(await future2, result)

            # Reset futures for exception test
            future1 = Future()
            future2 = Future()
            chain_future(future1, future2)

            # Set an exception on future1 and check if future2 gets the same exception
            try:
                raise ValueError("test exception")
            except ValueError as e:
                future1.set_exception(e)

            with self.assertRaises(ValueError) as context:
                await future2
            self.assertEqual(str(context.exception), "test exception")

            # Test that if future

# Generated at 2024-03-18 08:21:57.717260
```python
    from tornado.concurrent import Future, chain_future
    import unittest

    class TestChainFuture(unittest.TestCase):
        def test_chain_success(self):
            a = Future()
            b = Future()
            chain_future(a, b)
            result = object()
            a.set_result(result)
            self.assertTrue(b.done())
            self.assertEqual(b.result(), result)

        def test_chain_exception(self):
            a = Future()
            b = Future()
            chain_future(a, b)
            try:
                raise Exception("Test exception")
            except Exception as e:
                a.set_exception(e)
            self.assertTrue(b.done())
            self.assertIsInstance(b.exception(), Exception)
            self.assertEqual(str(b.exception()), "Test exception")

        def test_chain_cancelled(self):
            a = Future()
            b = Future()
            chain_future(a, b)
            b.cancel()
            a.set_result(object())
            self.assertTrue(b.cancelled())

        def test_chain_already_done(self):
            a = Future()


# Generated at 2024-03-18 08:22:04.312872
```python
    from tornado.concurrent import Future, chain_future
    import unittest

    class TestChainFuture(unittest.TestCase):
        def test_chain_success(self):
            a = Future()
            b = Future()
            chain_future(a, b)
            a.set_result(42)
            self.assertEqual(b.result(), 42)

        def test_chain_exception(self):
            a = Future()
            b = Future()
            chain_future(a, b)
            try:
                raise Exception("Test exception")
            except Exception as e:
                a.set_exception(e)
            with self.assertRaises(Exception) as context:
                b.result()
            self.assertEqual(str(context.exception), "Test exception")

        def test_chain_cancelled(self):
            a = Future()
            b = Future()
            chain_future(a, b)
            b.cancel()
            a.set_result(42)
            self.assertTrue(b.cancelled())

    if __name__ == '__main__':
        unittest.main()
```

# Generated at 2024-03-18 08:22:11.175596
```python
    from tornado.concurrent import Future, chain_future
    import unittest

    class TestChainFuture(unittest.TestCase):
        def test_chain_success(self):
            a = Future()
            b = Future()
            chain_future(a, b)
            result = object()
            a.set_result(result)
            self.assertTrue(b.done())
            self.assertEqual(b.result(), result)

        def test_chain_exception(self):
            a = Future()
            b = Future()
            chain_future(a, b)
            try:
                raise Exception("Test exception")
            except Exception as e:
                a.set_exception(e)
            self.assertTrue(b.done())
            self.assertIsInstance(b.exception(), Exception)
            self.assertEqual(str(b.exception()), "Test exception")

        def test_chain_cancelled(self):
            a = Future()
            b = Future()
            chain_future(a, b)
            b.cancel()
            a.set_result(object())
            self.assertTrue(b.cancelled())

        def test_chain_already_done(self):
            a = Future()


# Generated at 2024-03-18 08:22:11.983408
```python
import unittest
from unittest.mock import Mock


# Generated at 2024-03-18 08:22:13.109474
```python
import unittest
from unittest.mock import Mock


# Generated at 2024-03-18 08:22:19.653032
```python
    from tornado.concurrent import Future, chain_future
    import unittest

    class TestChainFuture(unittest.TestCase):
        def test_chain_success(self):
            a = Future()
            b = Future()
            chain_future(a, b)
            result = object()
            a.set_result(result)
            self.assertTrue(b.done())
            self.assertEqual(b.result(), result)

        def test_chain_exception(self):
            a = Future()
            b = Future()
            chain_future(a, b)
            try:
                raise Exception("Test exception")
            except Exception as e:
                a.set_exception(e)
            self.assertTrue(b.done())
            self.assertIsInstance(b.exception(), Exception)
            self.assertEqual(str(b.exception()), "Test exception")

        def test_chain_cancelled(self):
            a = Future()
            b = Future()
            chain_future(a, b)
            b.cancel()
            a.set_result(object())
            self.assertTrue(b.cancelled())

    unittest.main()
```

# Generated at 2024-03-18 08:22:23.433143
```python
    try:
        future = Future()
        future.cancel()
        exc = Exception("Test exception")
        future_set_exception_unless_cancelled(future, exc)
        assert future.cancelled()
        assert not future.done()

        future = Future()
        future_set_exception_unless_cancelled(future, exc)
        assert future.done()
        assert future.exception() is exc
    except Exception as e:
        assert False, f"Unexpected exception raised: {e}"
```

# Generated at 2024-03-18 08:22:30.477195
```python
    a = Future()
    b = Future()

    chain_future(a, b)

    # Test chaining success
    result = "success"
    a.set_result(result)
    assert b.result() == result, "Chained future did not get the correct result on success."

    # Test chaining exception
    a = Future()
    b = Future()
    chain_future(a, b)

    try:
        raise ValueError("chained exception")
    except ValueError:
        a.set_exception(sys.exc_info()[1])

    assert b.exception().args == ("chained exception",), "Chained future did not get the correct exception."

    # Test that b does not change if it's already done
    a = Future()
    b = Future()
    chain_future(a, b)

    b.set_result("b's result")
    a.set_result("a's result")
    assert b.result() == "b's result", "Chained future changed result after being completed

# Generated at 2024-03-18 08:22:41.415401
```python
    from tornado.concurrent import Future, chain_future
    import unittest

    class TestChainFuture(unittest.TestCase):
        def test_chain_success(self):
            a = Future()
            b = Future()
            chain_future(a, b)
            result = object()
            a.set_result(result)
            self.assertTrue(b.done())
            self.assertEqual(b.result(), result)

        def test_chain_exception(self):
            a = Future()
            b = Future()
            chain_future(a, b)
            try:
                raise Exception("Test exception")
            except Exception as e:
                a.set_exception(e)
            self.assertTrue(b.done())
            self.assertIsInstance(b.exception(), Exception)
            self.assertEqual(str(b.exception()), "Test exception")

        def test_chain_cancelled(self):
            a = Future()
            b = Future()
            chain_future(a, b)
            b.cancel()
            a.set_result(object())
            self.assertTrue(b.cancelled())

        def test_chain_already_done(self):
            a = Future()


# Generated at 2024-03-18 08:23:49.659487
```python
import unittest
from unittest.mock import Mock


# Generated at 2024-03-18 08:23:55.212174
```python
    # Create a Future object
    future = Future()

    # Set an exception on the future unless it is cancelled
    exc = Exception("Test exception")
    future_set_exception_unless_cancelled(future, exc)

    # Check if the future has the exception set
    assert future.exception() == exc, "The future should have the exception set"

    # Cancel the future
    future.cancel()

    # Try setting another exception, which should not be set due to cancellation
    another_exc = Exception("Another test exception")
    future_set_exception_unless_cancelled(future, another_exc)

    # The future should still have the original exception
    assert future.exception() == exc, "The future should still have the original exception after cancellation"

    # The future should be cancelled
    assert future.cancelled(), "The future should be cancelled"

    print("test_future_set_exception_unless_cancelled passed.")
```

# Generated at 2024-03-18 08:24:09.773190
```python
    from tornado.testing import AsyncTestCase, gen_test

    class TestChainFuture(AsyncTestCase):
        @gen_test
        async def test_chain(self):
            future1 = Future()
            future2 = Future()

            chain_future(future1, future2)

            # Set a result on future1 and ensure it propagates to future2
            result = "test result"
            future1.set_result(result)
            self.assertEqual(await future2, result)

            # Reset futures for exception test
            future1 = Future()
            future2 = Future()
            chain_future(future1, future2)

            # Set an exception on future1 and ensure it propagates to future2
            try:
                raise ValueError("test exception")
            except ValueError as e:
                future1.set_exception(e)

            with self.assertRaises(ValueError):
                await future2

            # Test that cancelling future2 does not affect future1
            future1 = Future()
            future2

# Generated at 2024-03-18 08:24:17.332815
```python
    from tornado.concurrent import Future, chain_future
    import unittest

    class TestChainFuture(unittest.TestCase):
        def test_chain_success(self):
            a = Future()
            b = Future()
            chain_future(a, b)
            result = object()
            a.set_result(result)
            self.assertTrue(b.done())
            self.assertEqual(b.result(), result)

        def test_chain_exception(self):
            a = Future()
            b = Future()
            chain_future(a, b)
            try:
                raise Exception("Test exception")
            except Exception as e:
                a.set_exception(e)
            self.assertTrue(b.done())
            self.assertIsInstance(b.exception(), Exception)
            self.assertEqual(str(b.exception()), "Test exception")

        def test_chain_cancelled(self):
            a = Future()
            b = Future()
            chain_future(a, b)
            b.cancel()
            a.set_result(object())
            self.assertTrue(b.cancelled())

        def test_chain_already_done(self):
            a = Future()


# Generated at 2024-03-18 08:24:25.277455
```python
    from tornado.concurrent import Future, chain_future
    import unittest

    class TestChainFuture(unittest.TestCase):
        def test_chain_success(self):
            a = Future()
            b = Future()
            chain_future(a, b)
            result = object()
            a.set_result(result)
            self.assertTrue(b.done())
            self.assertEqual(b.result(), result)

        def test_chain_exception(self):
            a = Future()
            b = Future()
            chain_future(a, b)
            try:
                raise Exception("Test exception")
            except Exception as e:
                a.set_exception(e)
            self.assertTrue(b.done())
            self.assertIsInstance(b.exception(), Exception)
            self.assertEqual(str(b.exception()), "Test exception")

        def test_chain_cancelled(self):
            a = Future()
            b = Future()
            chain_future(a, b)
            b.cancel()
            a.set_result(object())
            self.assertTrue(b.cancelled())

    if __name__ == "__main__":
        unittest.main()


# Generated at 2024-03-18 08:24:26.462476
```python
import unittest


# Generated at 2024-03-18 08:24:36.400265
```python
    # Assume the following imports have been made for the test context
    import unittest
    from unittest.mock import Mock

    class TestFutureSetExceptionUnlessCancelled(unittest.TestCase):
        def test_set_exception_on_non_cancelled_future(self):
            future = Future()
            exception = Exception("Test exception")
            future_set_exception_unless_cancelled(future, exception)
            self.assertTrue(future.done())
            self.assertEqual(future.exception(), exception)

        def test_no_set_exception_on_cancelled_future(self):
            future = Future()
            future.cancel()
            exception = Exception("Test exception")
            future_set_exception_unless_cancelled(future, exception)
            self.assertTrue(future.cancelled())
            self.assertIsNone(future.exception())

        def test_logging_on_cancelled_future(self):
            future = Future()
            future.cancel()
            exception = Exception("Test exception")
            with self.assertLogs('tornado.application', level='ERROR') as cm:
                future_set_exception_un

# Generated at 2024-03-18 08:24:40.176190
```python
    # Create a normal future and a cancelled future
    normal_future = Future()
    cancelled_future = Future()
    cancelled_future.cancel()

    # Set results
    future_set_result_unless_cancelled(normal_future, "normal result")
    future_set_result_unless_cancelled(cancelled_future, "cancelled result")

    # Check results
    assert normal_future.result() == "normal result", "The result should be set to 'normal result'"
    assert cancelled_future.cancelled(), "The future should remain cancelled"
```

# Generated at 2024-03-18 08:24:47.962142
```python
    # Assume the following imports have been made for the test context
    import unittest
    from unittest.mock import Mock

    class TestFutureSetExceptionUnlessCancelled(unittest.TestCase):
        def test_set_exception_on_non_cancelled_future(self):
            future = Future()
            exception = Exception("Test exception")
            future_set_exception_unless_cancelled(future, exception)
            self.assertTrue(future.done())
            self.assertEqual(future.exception(), exception)

        def test_no_exception_on_cancelled_future(self):
            future = Future()
            future.cancel()
            exception = Exception("Test exception")
            future_set_exception_unless_cancelled(future, exception)
            self.assertTrue(future.cancelled())
            self.assertIsNone(future.exception())

        def test_logging_on_cancelled_future(self):
            future = Future()
            future.cancel()
            exception = Exception("Test exception")
            with self.assertLogs('tornado.application', level='ERROR') as cm:
                future_set_exception_unless

# Generated at 2024-03-18 08:24:54.128561
```python
    from tornado.concurrent import Future, chain_future
    import unittest

    class TestChainFuture(unittest.TestCase):
        def test_chain_success(self):
            a = Future()
            b = Future()
            chain_future(a, b)
            result = object()
            a.set_result(result)
            self.assertTrue(b.done())
            self.assertEqual(b.result(), result)

        def test_chain_exception(self):
            a = Future()
            b = Future()
            chain_future(a, b)
            try:
                raise Exception("Test exception")
            except Exception as e:
                a.set_exception(e)
            self.assertTrue(b.done())
            self.assertIsInstance(b.exception(), Exception)
            self.assertEqual(str(b.exception()), "Test exception")

        def test_chain_cancelled(self):
            a = Future()
            b = Future()
            chain_future(a, b)
            b.cancel()
            a.set_result(object())
            self.assertTrue(b.cancelled())

    unittest.main()
```